==== 平面结构图 ====
{{layered blueprint|name=
Desert Armorer 1|default=第3层
|S=Sand
|C=Cut Sandstone
|M=Smooth Sandstone
|O=Smooth Sandstone Slab+bottom
|G=Granite
|B=Blast Furnace
|T=Smooth Sandstone Stairs-rot90
|t=Smooth Sandstone Stairs-rot270
|J=Jungle Fence
|W=Wall Torch-rot-90
|N=Stone Button
|R=Granite Stairs-rot90
|r=Granite Stairs-rot270
|U=Jungle Door+bottom
|L=Jungle Door+top
|A=Wall Torch
|I=Granite Wall
|H=Wall Torch-rot-270

|----第1层|

SSSSSSS
SMSSSMS
SMMMMMS
SMMMMMS
SSMMMSS
 SMMMS 
 SSMSS 

|----第2层|

CMMMMMC
M GBG M
M     M
Mt   TM
CM   MC
 M   M 
 CMUMC 

|----第3层|

CMMMMMC
MWGGGHM
M NNN M
M     M
CM   MC
 J   J 
 CMLMC 

|----第4层|

CMMMMMC
M RGr M
M     M
M     M
CM   MC
 M A M 
 CMMMC 

|----第5层|

CMMMMMC
M  G  M
M     M
M     M
CMMMMMC
 OOOOO 
 COMOC 

|----第6层|

COMOMOC
OOOIOOO
MOOOOOM
OOOOOOO
COMOMOC
       
       

|----第7层|

       
   I   
       
       
       
       
       


}}<noinclude>
[[en:Village/Structure/Blueprints/Desert armorer 1 blueprint]]
[[fr:Village/Structure/Désert Armurier 1 plan]]
[[ja:村/構造/設計図/砂漠の防具鍛冶の家1]]
</noinclude>
