==== 平面结构图 ====
{{layered blueprint
|name=Village Plains Houses plains_small_house_1'''
|default=第3层
|S=Stripped Oak Log+top
|C=Cobblestone
|P=Oak Planks
|B=White Bed+top foot-rot270'''
|b=White Bed+top head-rot270
|<=Oak Stairs-rot90
|^=Oak Stairs-rot270
|g=glass Pane
|s=Oak Stairs-rot180
|T=torch-rot180
|d=Oak Door+bottom
|D=Oak Door+top
|G=glass Pane-rot90
|>=Oak Stairs
|----第1层|

        
  SCCCS 
  CPPPC 
  CPPPC 
  CPPPC 
  SCCCS 
    s   

|----第2层|

        
  SCCCS 
  Cb sC 
  CB  C 
  C   C 
  SCdCS 
        

|----第3层|

        
  SCGCS 
  C   C 
  g   g 
  C   C 
  SCDCS 
   T T  

|----第4层|

        
  SCCCS 
  C T C 
  C   C 
  C   C 
  SCCCS 
        

|----第5层|

 ^^^^^^>
 <PPPPP>
 <P   P>
 <P   P>
 <P   P>
 <PPPPP>
 <ssssss

|----第6层|

        
  <^^^> 
  <PPP> 
  <P P> 
  <PPP> 
  sssss 
        

|----第7层|

        
        
   <^^  
   <P>  
   sss  
        
        

}}<noinclude>
[[en:Village/Structure/Blueprints/Plains small house 1 blueprint]]
[[fr:Village/Structure/Plaines Petite Maison 1 plan]]
[[ja:村/構造/設計図/平原の小さな家1]]
</noinclude>
