==== 平面结构图 ====
{{layered blueprint|name=
exported_blueprint|default=第1层
|A=Chiseled Bookshelf-rot0
|B=Oak Log+top
|C=Observer-rot0
|D=Obsidian
|E=Note Block
|F=Repeater-rot270
|G=Observer-rot270
|H=Observer-rot90
|I=Repeater-rot0
|J=Lever-rot180

|----第1层|




 AB
  C
  C

|----第2层|




DEFGH
  I
  J

|----第3层|








}}
